{
 "cells": [
  {
   "cell_type": "markdown",
   "id": "a1d90e0a",
   "metadata": {},
   "source": [
    "## Q1. Describe three applications for exception processing."
   ]
  },
  {
   "cell_type": "markdown",
   "id": "c6d807c7",
   "metadata": {},
   "source": [
    "Exception processing refers to the handling of unexpected or exceptional situations that can occur during the execution of a program or system. Here are three applications of exception processing:\n",
    "\n",
    "Error handling in software development: Exception processing is commonly used in software development to handle errors and exceptions that occur during the execution of a program. For example, if a program attempts to divide by zero or access a null reference, an exception will be thrown. The program can then use exception processing to catch the exception and take appropriate action, such as displaying an error message to the user or logging the error for later analysis.\n",
    "\n",
    "Transaction processing in databases: Exception processing is also used in database systems to ensure transactional integrity. When a transaction is executed, the database system may encounter errors or exceptions that could cause the transaction to fail. Exception processing is used to detect these errors and roll back the transaction to ensure that the database remains consistent and in a valid state.\n",
    "\n",
    "System monitoring and management: Exception processing can be used to monitor and manage complex systems, such as computer networks or industrial control systems. By setting up exception handling rules, administrators can receive alerts or take automatic corrective actions when certain conditions or events occur, such as a system outage or equipment failure. This can help prevent downtime, minimize damage, and improve system reliability and availability."
   ]
  },
  {
   "cell_type": "markdown",
   "id": "e84a10f9",
   "metadata": {},
   "source": [
    "## Q2. What happens if you don&#39;t do something extra to treat an exception?"
   ]
  },
  {
   "cell_type": "markdown",
   "id": "3cfe7a32",
   "metadata": {},
   "source": [
    "If you don't do something extra to treat an exception, the program or system will typically terminate abruptly and the user may see an error message or experience other unexpected behavior. This is because when an exception is thrown, the program or system is indicating that it has encountered an unexpected situation that it cannot handle on its own.\n",
    "\n",
    "If the exception is not caught and handled properly, the program or system will terminate with an unhandled exception error message. This can be frustrating and confusing for users, and can also lead to data loss, system instability, or other problems.\n",
    "\n",
    "In some cases, the exception may be caught by a higher-level error handler or by the operating system itself. However, this is not a reliable or recommended approach, as it can still result in unexpected behavior and can make it difficult to diagnose and fix the underlying problem.\n",
    "\n",
    "Therefore, it is important to implement proper exception handling techniques to ensure that unexpected situations are handled gracefully and the program or system can continue to function in a stable and predictable manner."
   ]
  },
  {
   "cell_type": "markdown",
   "id": "9277330b",
   "metadata": {},
   "source": [
    "## Q3. What are your options for recovering from an exception in your script?"
   ]
  },
  {
   "cell_type": "markdown",
   "id": "ad72c273",
   "metadata": {},
   "source": [
    "When an exception occurs in a script, there are several options for recovering from the exception:\n",
    "\n",
    "Catch and handle the exception: This is the most common approach for recovering from an exception. You can use a try-catch block to catch the exception and handle it appropriately. For example, you could display an error message to the user, log the error for later analysis, or retry the operation that caused the exception.\n",
    "\n",
    "Retry the operation: Depending on the nature of the exception, it may be possible to retry the operation that caused the exception. For example, if the exception was caused by a temporary network outage, you could retry the operation after a short delay.\n",
    "\n",
    "Roll back the transaction: If the exception occurred during a transaction, you may need to roll back the transaction to ensure data consistency. This typically involves undoing any changes that were made to the data during the transaction.\n",
    "\n",
    "Terminate the script: In some cases, it may not be possible to recover from an exception. If the exception represents a fatal error or the script is unable to continue, you may need to terminate the script.\n",
    "\n",
    "Ignore the exception: While not recommended, it is possible to simply ignore an exception and allow the script to continue executing. This approach should only be used in cases where the exception is not critical and will not affect the behavior or results of the script.\n",
    "\n",
    "It is important to choose the appropriate approach for recovering from an exception based on the nature of the exception and the specific requirements of the script.\n",
    "\n",
    "\n",
    "\n",
    "\n"
   ]
  },
  {
   "cell_type": "markdown",
   "id": "ba939f3f",
   "metadata": {},
   "source": [
    "## Q4. Describe two methods for triggering exceptions in your script."
   ]
  },
  {
   "cell_type": "markdown",
   "id": "6bf0c176",
   "metadata": {},
   "source": [
    "Sure, here are two methods for triggering exceptions in Python:\n",
    "\n",
    "Using the \"raise\" statement: In Python, you can use the \"raise\" statement to explicitly raise an exception in your script. The \"raise\" statement is followed by the type of the exception being raised, and optionally a message that provides additional information about the exception. For example, the following code raises a ValueError exception with a message:"
   ]
  },
  {
   "cell_type": "code",
   "execution_count": 1,
   "id": "37ae1135",
   "metadata": {},
   "outputs": [
    {
     "ename": "ValueError",
     "evalue": "Invalid value provided",
     "output_type": "error",
     "traceback": [
      "\u001b[1;31m---------------------------------------------------------------------------\u001b[0m",
      "\u001b[1;31mValueError\u001b[0m                                Traceback (most recent call last)",
      "Cell \u001b[1;32mIn[1], line 1\u001b[0m\n\u001b[1;32m----> 1\u001b[0m \u001b[38;5;28;01mraise\u001b[39;00m \u001b[38;5;167;01mValueError\u001b[39;00m(\u001b[38;5;124m\"\u001b[39m\u001b[38;5;124mInvalid value provided\u001b[39m\u001b[38;5;124m\"\u001b[39m)\n",
      "\u001b[1;31mValueError\u001b[0m: Invalid value provided"
     ]
    }
   ],
   "source": [
    "raise ValueError(\"Invalid value provided\")\n"
   ]
  },
  {
   "cell_type": "markdown",
   "id": "b9dfbf4c",
   "metadata": {},
   "source": [
    "Using built-in functions or methods: Many built-in functions and methods in Python can raise exceptions under certain conditions. For example, if you try to divide by zero using the \"/\" operator, a ZeroDivisionError exception will be raised. Similarly, if you try to access a key in a dictionary that does not exist, a KeyError exception will be raised.\n",
    "For example, the following code raises a ZeroDivisionError exception:"
   ]
  },
  {
   "cell_type": "code",
   "execution_count": 2,
   "id": "c2691cd2",
   "metadata": {},
   "outputs": [
    {
     "ename": "ZeroDivisionError",
     "evalue": "division by zero",
     "output_type": "error",
     "traceback": [
      "\u001b[1;31m---------------------------------------------------------------------------\u001b[0m",
      "\u001b[1;31mZeroDivisionError\u001b[0m                         Traceback (most recent call last)",
      "Cell \u001b[1;32mIn[2], line 3\u001b[0m\n\u001b[0;32m      1\u001b[0m a \u001b[38;5;241m=\u001b[39m \u001b[38;5;241m10\u001b[39m\n\u001b[0;32m      2\u001b[0m b \u001b[38;5;241m=\u001b[39m \u001b[38;5;241m0\u001b[39m\n\u001b[1;32m----> 3\u001b[0m result \u001b[38;5;241m=\u001b[39m \u001b[43ma\u001b[49m\u001b[43m \u001b[49m\u001b[38;5;241;43m/\u001b[39;49m\u001b[43m \u001b[49m\u001b[43mb\u001b[49m\n",
      "\u001b[1;31mZeroDivisionError\u001b[0m: division by zero"
     ]
    }
   ],
   "source": [
    "a = 10\n",
    "b = 0\n",
    "result = a / b\n"
   ]
  },
  {
   "cell_type": "markdown",
   "id": "d15c37b8",
   "metadata": {},
   "source": [
    "In addition to these methods, exceptions can also be raised by external libraries, modules, or system components that your script depends on. It is important to be aware of the possible exceptions that can be raised and to handle them appropriately in your script.\n",
    "\n",
    "\n",
    "\n",
    "\n"
   ]
  },
  {
   "cell_type": "markdown",
   "id": "729bf928",
   "metadata": {},
   "source": [
    "## Q5. Identify two methods for specifying actions to be executed at termination time, regardless of whether or not an exception exists."
   ]
  },
  {
   "cell_type": "markdown",
   "id": "22592b88",
   "metadata": {},
   "source": [
    "There are two methods in Python for specifying actions to be executed at termination time, regardless of whether or not an exception exists:\n",
    "\n",
    "Using the \"finally\" block: The \"finally\" block is a part of the try-catch-finally statement that allows you to specify code that will always be executed, regardless of whether or not an exception is raised. This is useful for cleaning up resources that were used during the execution of the try block. For example:"
   ]
  },
  {
   "cell_type": "markdown",
   "id": "380e9f2e",
   "metadata": {},
   "source": [
    "Using the \"atexit\" module: The \"atexit\" module provides a way to register functions that will be called when the Python interpreter is about to exit, either normally or due to an unhandled exception. This is useful for performing final cleanup tasks, such as closing open files or releasing shared resources. For example:"
   ]
  },
  {
   "cell_type": "code",
   "execution_count": 5,
   "id": "5b965cbd",
   "metadata": {},
   "outputs": [
    {
     "data": {
      "text/plain": [
       "<function __main__.cleanup()>"
      ]
     },
     "execution_count": 5,
     "metadata": {},
     "output_type": "execute_result"
    }
   ],
   "source": [
    "import atexit\n",
    "\n",
    "def cleanup():\n",
    "    pass\n",
    "    # code to perform cleanup tasks\n",
    "\n",
    "atexit.register(cleanup)\n"
   ]
  },
  {
   "cell_type": "markdown",
   "id": "06257b7e",
   "metadata": {},
   "source": [
    "The \"atexit\" module can be used to register any number of functions that will be executed in the order in which they were registered. Note that functions registered with the \"atexit\" module will only be executed if the Python interpreter is allowed to exit normally. If the interpreter is terminated abruptly, such as by a system crash or a call to the \"os._exit()\" function, the registered functions will not be executed."
   ]
  },
  {
   "cell_type": "code",
   "execution_count": null,
   "id": "9d06aaaf",
   "metadata": {},
   "outputs": [],
   "source": []
  }
 ],
 "metadata": {
  "kernelspec": {
   "display_name": "Python 3 (ipykernel)",
   "language": "python",
   "name": "python3"
  },
  "language_info": {
   "codemirror_mode": {
    "name": "ipython",
    "version": 3
   },
   "file_extension": ".py",
   "mimetype": "text/x-python",
   "name": "python",
   "nbconvert_exporter": "python",
   "pygments_lexer": "ipython3",
   "version": "3.10.9"
  }
 },
 "nbformat": 4,
 "nbformat_minor": 5
}
